<?xml version="1.0" ?>

<!--Created by Alphonsus Adu-Bredu
	Assistive Robotics Group, Tufts University
    Email: alphonsusbq436@gmail.com
-->
<robot name="bill" xmlns:xacro="http://www.ros.org/wiki/xacro">

	<gazebo>
	  <plugin name="gazebo_ros_control" filename="libgazebo_ros_control.so">
	    <robotNamespace>/bill</robotNamespace>
	    <robotSimType>gazebo_ros_control/DefaultRobotHWSim</robotSimType>
	  </plugin>
	</gazebo>

	<gazebo>
		<plugin name="p3d_base_controller" filename="libgazebo_ros_p3d.so">
			<alwaysOn>true</alwaysOn>
			<updateRate>50.0</updateRate>
			<bodyName>base_link</bodyName>
			<topicName>odom</topicName>
			<gaussianNoise>0.01</gaussianNoise>
			<frameName>map</frameName>
			<xyzOffsets>0 0 0</xyzOffsets>
			<rpyOffsets>0 0 0</rpyOffsets>
		</plugin>
	</gazebo>

	<material name="black">
		<color rgba="0.0 0.0 0.0 1.0"/>
	</material>
	<material name="blue">
		<color rgba="0.203125 0.23828125 0.28515625 1.0"/>
	</material>
	<material name="green">
		<color rgba="0.0 0.8 0.0 1.0"/>
	</material>
	<material name="grey">
		<color rgba="0.2 0.2 0.2 1.0"/>
	</material>
	<material name="orange">
		<color rgba="1.0 0.423529411765 0.0392156862745 1.0"/>
	</material>
	<material name="brown">
		<color rgba="0.870588235294 0.811764705882 0.764705882353 1.0"/>
	</material>
	<material name="red">
		<color rgba="0.80078125 0.12890625 0.1328425 1.0"/>
	</material>
	<material name="white">
		<color rgba="1.0 1.0 1.0 1.0"/>
	</material>


	<gazebo reference="base_link">
		<material>Gazebo/Blue</material>
	</gazebo>

	<gazebo reference="caster">
		<material>Gazebo/Black</material>
	</gazebo>
	<gazebo reference="left_wheel">
		<material>Gazebo/Black</material>
	</gazebo>
	<gazebo reference="right_wheel">
		<material>Gazebo/Black</material>
	</gazebo>
	
	<link name="base_link"/>

	<link name="chassis">
		<!--pose and inertial-->
		<pose>0 0 0.1 0 0 0 </pose>
		<inertial>
			<mass value="15"/>
			<origin rpy="0 0 0" xyz="0 0 0.1"/>
			<inertia ixx="0.0395416666667" ixy="0" ixz="0" iyy="0.106208333333" iyz="0.106208333333" izz="0"/>
		</inertial>

		<!--body-->
		<collision name="collision_chassis">
			<geometry>
				<box size="0.9 0.6 0.24"/>
			</geometry>
		</collision>

		<visual>
			<origin rpy="0 0 0" xyz="0 0 0"/>
			<geometry>
				<box size="0.9 0.6 0.24"/>
			</geometry>
			<material name="blue"/>
		</visual>
	</link>

	<joint name="base_link_joint" type="fixed" >
		<parent link="base_link"/>
		<child link="chassis"/>		
		
	</joint>

		<!--caster front -->
		<link name="caster">
			<inertial>
				<mass value="0.5"/>
				<origin rpy="1.57079632679 0 0" xyz="0 0 0"/>
				<inertia ixx="0.001" ixy="0" ixz="0" iyy="0.001" iyz="0" izz="0.001"/>
			</inertial>

		<collision name="caster_front_collision">
			<origin rpy="1.57079632679 0 0" xyz="0 0 -0.1"/>
			<geometry>
				<sphere radius="0.07"/>
			</geometry>
			<surface>
				<friction>
					<ode>
						<mu>0</mu>
						<mu2>0</mu2>
						<slip1>1.0</slip1>
						<slip2>1.0</slip2>
					</ode>
				</friction>
			</surface>
		</collision>

		<visual name="caster_front_visual">
			<origin rpy="1.57079632679 0 0" xyz="0 0 -0.1"/>
			<geometry>
				<sphere radius="0.07"/>
			</geometry>
			<material name="black"/>
		</visual>
	</link>

	<joint name="caster_front_joint" type="fixed">
	    <parent link="chassis"/>
	    <child link="caster"/>
	    <origin rpy="-1.57079632679 0 0" xyz="0.2 0.1 -0.1"/>
	</joint>

	  <gazebo reference="caster">
	    <turnGravityOff>false</turnGravityOff>
	  </gazebo>
	

	<link name="right_wheel">
		<inertial>
			<mass value="2"/>
			<origin rpy="0 1.5707 1.5707" xyz="0 0 0"/>
			<inertia ixx="0.000526666666667" ixy="0" ixz="0" iyy="0.000526666666667" iyz="0" izz="0.001"/>
		</inertial>

		<collision name="right_wheel_collision">
			<origin rpy="0 1.5707 1.5707" xyz="0 0 0"/>
			<geometry>
				<cylinder length="0.07" radius="0.162"/>
			</geometry>
		</collision>

		<visual name="right_wheel_visual">
			<origin rpy="0 1.5707 1.5707" xyz="0 0 0"/>
			<geometry>
				<cylinder length="0.07" radius="0.162"/>
			</geometry>
			<material name="black"/>
		</visual>
	</link>

	<joint name="right_wheel_joint" type="continuous">
		<origin rpy="0 0 0" xyz="-0.1 0.20 0"/>
		<child link="right_wheel"/>
		<parent link="chassis"/>
		<axis rpy="0 0 0" xyz="0 1 0"/>
		<limit effort="10000" velocity="1000"/>
		<joint_properties damping="1.0" friction="1.0"/>
	</joint>


	<link name="left_wheel">
		<inertial>
			<mass value="2"/>
			<origin rpy="0 1.5707 1.5707" xyz="0 0 0"/>
			<inertia ixx="0.000526666666667" ixy="0" ixz="0" iyy="0.000526666666667" iyz="0" izz="0.001"/>
		</inertial>

		<collision name="left_wheel_collision">
			<origin rpy="0 1.5707 1.5707" xyz="0 0 0"/>
			<geometry>
				<cylinder length="0.07" radius="0.162"/>
			</geometry>
		</collision>

		<visual name="left_wheel_visual">
			<origin rpy="0 1.5707 1.5707" xyz="0 0 0"/>
			<geometry>
				<cylinder length="0.07" radius="0.162"/>
			</geometry>
			<material name="black"/>
		</visual>
	</link>

	<joint name="left_wheel_joint" type="continuous">
		<origin rpy="0 0 0" xyz="-0.1 -0.20 0"/>
		<child link="left_wheel"/>
		<parent link="chassis"/>
		<axis rpy="0 0 0" xyz="0 1 0"/>
		<limit effort="10000" velocity="1000"/>
		<joint_properties damping="1.0" friction="1.0"/>
	</joint>


	<!--IMU-->
	<link name="imu">
	    <visual>
	      <origin rpy="0 0 0" xyz="0  0  0"/>
	      <geometry>
	        <box size="0.05 0.05 0.05"/>
	      </geometry>
	      <material name="white"/>
	    </visual>

	    <collision>
	      <origin rpy="0 0 0" xyz="0.15  0.13  0.07"/>
	      <geometry>
	        <box size="0.05 0.05 0.05"/>
	      </geometry>
	      <material name="white"/>
	    </collision>

	    <inertial>
		  <origin xyz="0 0 0.015" rpy="0 0 0"/>
		  <mass value="0.01"/>
		  <inertia
		    ixx="1.0" ixy="0.0" ixz="0.0"
		    iyy="1.0" iyz="0.0"
		    izz="1.0"/>
		</inertial>
	</link>

	<joint name="imu_joint" type="fixed" >
		<parent link="chassis"/>
		<child link="imu"/>
		<origin xyz="0.0 0 0.1" rpy="0 0 0"/>		
	</joint>

	<gazebo reference="imu">
    <gravity>true</gravity>
    <sensor name="imu_sensor" type="imu">
      <always_on>true</always_on>
      <update_rate>100</update_rate>
      <visualize>true</visualize>
      <topic>__default_topic__</topic>
      <plugin filename="libgazebo_ros_imu_sensor.so" name="imu_plugin">
        <topicName>imu</topicName>
        <bodyName>imu</bodyName>
        <updateRateHZ>10.0</updateRateHZ>
        <gaussianNoise>0.0</gaussianNoise>
        <xyzOffset>0 0 0</xyzOffset>
        <rpyOffset>0 0 0</rpyOffset>
        <frameName>imu</frameName>
      </plugin>
      <pose>0 0 0 0 0 0</pose>
    </sensor>
  </gazebo>


	<transmission name="tran1">
			<type>transmission_interface/SimpleTransmission</type>
			<joint name ="left_wheel_joint">
				<hardwareInterface>hardware_interface/EffortJointInterface</hardwareInterface>
			</joint>
			<actuator name="motor1">
		      <hardwareInterface>EffortJointInterface</hardwareInterface>
		      <mechanicalReduction>1</mechanicalReduction>
		    </actuator>
	</transmission>


	<transmission name="tran2">
			<type>transmission_interface/SimpleTransmission</type>
			<joint name ="right_wheel_joint">
				<hardwareInterface>hardware_interface/EffortJointInterface</hardwareInterface>
			</joint>
			<actuator name="motor2">
		      <hardwareInterface>EffortJointInterface</hardwareInterface>
		      <mechanicalReduction>1</mechanicalReduction>
		    </actuator>
	</transmission>


</robot>