<sdf version='1.6'>
  <world name='default'>
    <light name='sun' type='directional'>
      <cast_shadows>1</cast_shadows>
      <pose frame=''>0 0 10 0 -0 0</pose>
      <diffuse>0.8 0.8 0.8 1</diffuse>
      <specular>0.1 0.1 0.1 1</specular>
      <attenuation>
        <range>1000</range>
        <constant>0.9</constant>
        <linear>0.01</linear>
        <quadratic>0.001</quadratic>
      </attenuation>
      <direction>-0.5 0.5 -1</direction>
    </light>
    <model name='ground_plane'>
      <static>1</static>
      <link name='link'>
        <collision name='collision'>
          <geometry>
            <plane>
              <normal>0 0 1</normal>
              <size>100 100</size>
            </plane>
          </geometry>
          <surface>
            <friction>
              <ode>
                <mu>100</mu>
                <mu2>50</mu2>
              </ode>
              <torsional>
                <ode/>
              </torsional>
            </friction>
            <contact>
              <ode/>
            </contact>
            <bounce/>
          </surface>
          <max_contacts>10</max_contacts>
        </collision>
        <visual name='visual'>
          <cast_shadows>0</cast_shadows>
          <geometry>
            <plane>
              <normal>0 0 1</normal>
              <size>100 100</size>
            </plane>
          </geometry>
          <material>
            <script>
              <uri>file://media/materials/scripts/gazebo.material</uri>
              <name>Gazebo/Grey</name>
            </script>
          </material>
        </visual>
        <self_collide>0</self_collide>
        <kinematic>0</kinematic>
      </link>
    </model>
    <gravity>0 0 -9.8</gravity>
    <magnetic_field>6e-06 2.3e-05 -4.2e-05</magnetic_field>
    <atmosphere type='adiabatic'/>
    <physics name='default_physics' default='0' type='ode'>
      <max_step_size>0.001</max_step_size>
      <real_time_factor>1</real_time_factor>
      <real_time_update_rate>1000</real_time_update_rate>
    </physics>
    <scene>
      <ambient>0.4 0.4 0.4 1</ambient>
      <background>0.7 0.7 0.7 1</background>
      <shadows>1</shadows>
    </scene>
    <spherical_coordinates>
      <surface_model>EARTH_WGS84</surface_model>
      <latitude_deg>0</latitude_deg>
      <longitude_deg>0</longitude_deg>
      <elevation>0</elevation>
      <heading_deg>0</heading_deg>
    </spherical_coordinates>
    <model name='bill'>
      <link name='base_link'>
        <pose frame=''>0 0 0 0 -0 0</pose>
        <inertial>
          <pose frame=''>-0.03636 0.099991 -0.099981 0 -0 0</pose>
          <mass>1.1001</mass>
          <inertia>
            <ixx>1.00201</ixx>
            <ixy>3.63603e-07</ixy>
            <ixz>-7.81747e-07</ixz>
            <iyy>1.17655</iyy>
            <iyz>2.1498e-06</iyz>
            <izz>1.17655</izz>
          </inertia>
        </inertial>
        <collision name='base_link_fixed_joint_lump__collision_chassis_collision'>
          <pose frame=''>0 0 0 0 -0 0</pose>
          <geometry>
            <box>
              <size>1 0.6 0.24</size>
            </box>
          </geometry>
          <max_contacts>10</max_contacts>
          <surface>
            <contact>
              <ode/>
            </contact>
            <bounce/>
            <friction>
              <torsional>
                <ode/>
              </torsional>
              <ode/>
            </friction>
          </surface>
        </collision>
        <collision name='base_link_fixed_joint_lump__caster_back_collision_collision_1'>
          <pose frame=''>-0.4 0 -0.1 0 -0 0</pose>
          <geometry>
            <sphere>
              <radius>0.06</radius>
            </sphere>
          </geometry>
          <max_contacts>10</max_contacts>
          <surface>
            <contact>
              <ode/>
            </contact>
            <bounce/>
            <friction>
              <torsional>
                <ode/>
              </torsional>
              <ode/>
            </friction>
          </surface>
        </collision>
        <collision name='base_link_fixed_joint_lump__caster_front_collision_collision_2'>
          <pose frame=''>0.4 0 -0.1 0 -0 0</pose>
          <geometry>
            <sphere>
              <radius>0.06</radius>
            </sphere>
          </geometry>
          <max_contacts>10</max_contacts>
          <surface>
            <contact>
              <ode/>
            </contact>
            <bounce/>
            <friction>
              <torsional>
                <ode/>
              </torsional>
              <ode/>
            </friction>
          </surface>
        </collision>
        <collision name='base_link_fixed_joint_lump__imu_collision_3'>
          <pose frame=''>0 0 0.1 0 -0 0</pose>
          <geometry>
            <box>
              <size>0.05 0.05 0.05</size>
            </box>
          </geometry>
          <surface>
            <contact>
              <ode/>
            </contact>
            <friction>
              <ode/>
              <torsional>
                <ode/>
              </torsional>
            </friction>
            <bounce/>
          </surface>
          <max_contacts>10</max_contacts>
        </collision>
        <collision name='base_link_fixed_joint_lump__rplidar_collision_4'>
          <pose frame=''>0.42 0 0.1 0 -0 0</pose>
          <geometry>
            <cylinder>
              <length>0.1</length>
              <radius>0.05</radius>
            </cylinder>
          </geometry>
          <surface>
            <contact>
              <ode/>
            </contact>
            <friction>
              <ode/>
              <torsional>
                <ode/>
              </torsional>
            </friction>
            <bounce/>
          </surface>
          <max_contacts>10</max_contacts>
        </collision>
        <visual name='base_link_fixed_joint_lump__chassis_visual'>
          <pose frame=''>0 0 0 0 -0 0</pose>
          <geometry>
            <box>
              <size>1 0.6 0.24</size>
            </box>
          </geometry>
          <material>
            <script>
              <name>Gazebo/White</name>
              <uri>file://media/materials/scripts/gazebo.material</uri>
            </script>
          </material>
        </visual>
        <visual name='base_link_fixed_joint_lump__caster_back_visual_visual_1'>
          <pose frame=''>-0.4 0 -0.1 0 -0 0</pose>
          <geometry>
            <sphere>
              <radius>0.06</radius>
            </sphere>
          </geometry>
        </visual>
        <visual name='base_link_fixed_joint_lump__caster_front_visual_visual_2'>
          <pose frame=''>0.4 0 -0.1 0 -0 0</pose>
          <geometry>
            <sphere>
              <radius>0.06</radius>
            </sphere>
          </geometry>
        </visual>
        <visual name='base_link_fixed_joint_lump__imu_visual_3'>
          <pose frame=''>0 0 0.1 0 -0 0</pose>
          <geometry>
            <box>
              <size>0.05 0.05 0.05</size>
            </box>
          </geometry>
          <material>
            <script>
              <name>Gazebo/Blue</name>
              <uri>file://media/materials/scripts/gazebo.material</uri>
            </script>
          </material>
        </visual>
        <visual name='base_link_fixed_joint_lump__rplidar_visual_4'>
          <pose frame=''>0.42 0 0.1 0 -0 0</pose>
          <geometry>
            <cylinder>
              <length>0.1</length>
              <radius>0.05</radius>
            </cylinder>
          </geometry>
          <material>
            <script>
              <name>Gazebo/Green</name>
              <uri>file://media/materials/scripts/gazebo.material</uri>
            </script>
          </material>
        </visual>
        <velocity_decay/>
        <velocity_decay/>
        <velocity_decay/>
        <velocity_decay/>
        <velocity_decay/>
        <gravity>1</gravity>
        <sensor name='imu_sensor' type='imu'>
          <always_on>1</always_on>
          <update_rate>100</update_rate>
          <visualize>1</visualize>
          <topic>__default_topic__</topic>
          <plugin name='imu_plugin' filename='libgazebo_ros_imu_sensor.so'>
            <topicName>/imu</topicName>
            <bodyName>imu</bodyName>
            <updateRateHZ>10.0</updateRateHZ>
            <gaussianNoise>0.0</gaussianNoise>
            <xyzOffset>0 0 0</xyzOffset>
            <rpyOffset>0 0 0</rpyOffset>
            <frameName>imu</frameName>
            <robotNamespace>/</robotNamespace>
          </plugin>
          <pose frame=''>0 0 0.1 0 -0 0</pose>
        </sensor>
        <gravity>1</gravity>
        <velocity_decay/>
        <self_collide>0</self_collide>
        <sensor name='head_hokuyo_sensor' type='ray'>
          <visualize>0</visualize>
          <update_rate>40</update_rate>
          <ray>
            <scan>
              <horizontal>
                <samples>720</samples>
                <resolution>1</resolution>
                <min_angle>-1.5708</min_angle>
                <max_angle>1.5708</max_angle>
              </horizontal>
              <vertical>
                <samples>1</samples>
                <min_angle>0</min_angle>
                <max_angle>0</max_angle>
              </vertical>
            </scan>
            <range>
              <min>0.1</min>
              <max>50</max>
              <resolution>0.001</resolution>
            </range>
          </ray>
          <plugin name='gazebo_ros_head_hokuyo_controller' filename='libgazebo_ros_laser.so'>
            <topicName>/scan</topicName>
            <frameName>rplidar</frameName>
            <robotNamespace>/</robotNamespace>
          </plugin>
          <pose frame=''>0.42 0 0.1 0 -0 0</pose>
        </sensor>
        <kinematic>0</kinematic>
      </link>
      <link name='left_wheel'>
        <pose frame=''>0 -0.2 0 0 -0 0</pose>
        <inertial>
          <pose frame=''>0 0 0 -0 1.5707 1.5707</pose>
          <mass>1</mass>
          <inertia>
            <ixx>0.000526667</ixx>
            <ixy>0</ixy>
            <ixz>0</ixz>
            <iyy>0.000526667</iyy>
            <iyz>0</iyz>
            <izz>0.001</izz>
          </inertia>
        </inertial>
        <collision name='left_wheel_collision_collision'>
          <pose frame=''>0 0 0 3.14159 1.57079 -1.57089</pose>
          <geometry>
            <cylinder>
              <length>0.07</length>
              <radius>0.162</radius>
            </cylinder>
          </geometry>
          <surface>
            <contact>
              <ode/>
            </contact>
            <friction>
              <ode/>
              <torsional>
                <ode/>
              </torsional>
            </friction>
            <bounce/>
          </surface>
          <max_contacts>10</max_contacts>
        </collision>
        <visual name='left_wheel_visual_visual'>
          <pose frame=''>0 0 0 3.14159 1.57079 -1.57089</pose>
          <geometry>
            <cylinder>
              <length>0.07</length>
              <radius>0.162</radius>
            </cylinder>
          </geometry>
          <material>
            <script>
              <name>Gazebo/Black</name>
              <uri>file://media/materials/scripts/gazebo.material</uri>
            </script>
          </material>
        </visual>
        <gravity>1</gravity>
        <velocity_decay/>
        <self_collide>0</self_collide>
        <kinematic>0</kinematic>
      </link>
      <joint name='left_wheel_joint' type='revolute'>
        <child>left_wheel</child>
        <parent>base_link</parent>
        <axis>
          <xyz>0 1 0</xyz>
          <limit>
            <lower>-1e+16</lower>
            <upper>1e+16</upper>
          </limit>
          <dynamics>
            <spring_reference>0</spring_reference>
            <spring_stiffness>0</spring_stiffness>
          </dynamics>
          <use_parent_model_frame>1</use_parent_model_frame>
        </axis>
      </joint>
      <link name='right_wheel'>
        <pose frame=''>0 0.2 0 0 -0 0</pose>
        <inertial>
          <pose frame=''>0 0 0 -0 1.5707 1.5707</pose>
          <mass>1</mass>
          <inertia>
            <ixx>0.000526667</ixx>
            <ixy>0</ixy>
            <ixz>0</ixz>
            <iyy>0.000526667</iyy>
            <iyz>0</iyz>
            <izz>0.001</izz>
          </inertia>
        </inertial>
        <collision name='right_wheel_collision_collision'>
          <pose frame=''>0 0 0 3.14159 1.57079 -1.57089</pose>
          <geometry>
            <cylinder>
              <length>0.07</length>
              <radius>0.162</radius>
            </cylinder>
          </geometry>
          <surface>
            <contact>
              <ode/>
            </contact>
            <friction>
              <ode/>
              <torsional>
                <ode/>
              </torsional>
            </friction>
            <bounce/>
          </surface>
          <max_contacts>10</max_contacts>
        </collision>
        <visual name='right_wheel_visual_visual'>
          <pose frame=''>0 0 0 3.14159 1.57079 -1.57089</pose>
          <geometry>
            <cylinder>
              <length>0.07</length>
              <radius>0.162</radius>
            </cylinder>
          </geometry>
          <material>
            <script>
              <name>Gazebo/Black</name>
              <uri>file://media/materials/scripts/gazebo.material</uri>
            </script>
          </material>
        </visual>
        <gravity>1</gravity>
        <velocity_decay/>
        <self_collide>0</self_collide>
        <kinematic>0</kinematic>
      </link>
      <joint name='right_wheel_joint' type='revolute'>
        <child>right_wheel</child>
        <parent>base_link</parent>
        <axis>
          <xyz>0 1 0</xyz>
          <limit>
            <lower>-1e+16</lower>
            <upper>1e+16</upper>
          </limit>
          <dynamics>
            <spring_reference>0</spring_reference>
            <spring_stiffness>0</spring_stiffness>
          </dynamics>
          <use_parent_model_frame>1</use_parent_model_frame>
        </axis>
      </joint>
      <plugin name='gazebo_ros_control' filename='libgazebo_ros_control.so'>
        <robotNamespace>/bill</robotNamespace>
        <robotSimType>gazebo_ros_control/DefaultRobotHWSim</robotSimType>
      </plugin>
      <static>0</static>
      <plugin name='p3d_base_controller' filename='libgazebo_ros_p3d.so'>
        <alwaysOn>true</alwaysOn>
        <updateRate>50.0</updateRate>
        <bodyName>base_link</bodyName>
        <topicName>odom</topicName>
        <gaussianNoise>0.01</gaussianNoise>
        <frameName>map</frameName>
        <xyzOffsets>0 0 0</xyzOffsets>
        <rpyOffsets>0 0 0</rpyOffsets>
        <robotNamespace>/</robotNamespace>
      </plugin>
      <pose frame=''>0 0 0.5 0 -0 0</pose>
    </model>
    <model name='bookshelf'>
      <static>1</static>
      <link name='link'>
        <inertial>
          <mass>1</mass>
        </inertial>
        <collision name='back'>
          <pose frame=''>0 0.005 0.6 0 -0 0</pose>
          <geometry>
            <box>
              <size>0.9 0.01 1.2</size>
            </box>
          </geometry>
          <max_contacts>10</max_contacts>
          <surface>
            <contact>
              <ode/>
            </contact>
            <bounce/>
            <friction>
              <torsional>
                <ode/>
              </torsional>
              <ode/>
            </friction>
          </surface>
        </collision>
        <visual name='visual1'>
          <pose frame=''>0 0.005 0.6 0 -0 0</pose>
          <geometry>
            <box>
              <size>0.9 0.01 1.2</size>
            </box>
          </geometry>
          <material>
            <script>
              <uri>file://media/materials/scripts/gazebo.material</uri>
              <name>Gazebo/Wood</name>
            </script>
          </material>
        </visual>
        <collision name='left_side'>
          <pose frame=''>0.45 -0.195 0.6 0 -0 0</pose>
          <geometry>
            <box>
              <size>0.02 0.4 1.2</size>
            </box>
          </geometry>
          <max_contacts>10</max_contacts>
          <surface>
            <contact>
              <ode/>
            </contact>
            <bounce/>
            <friction>
              <torsional>
                <ode/>
              </torsional>
              <ode/>
            </friction>
          </surface>
        </collision>
        <visual name='visual2'>
          <pose frame=''>0.45 -0.195 0.6 0 -0 0</pose>
          <geometry>
            <box>
              <size>0.02 0.4 1.2</size>
            </box>
          </geometry>
          <material>
            <script>
              <uri>file://media/materials/scripts/gazebo.material</uri>
              <name>Gazebo/Wood</name>
            </script>
          </material>
        </visual>
        <collision name='right_side'>
          <pose frame=''>-0.45 -0.195 0.6 0 -0 0</pose>
          <geometry>
            <box>
              <size>0.02 0.4 1.2</size>
            </box>
          </geometry>
          <max_contacts>10</max_contacts>
          <surface>
            <contact>
              <ode/>
            </contact>
            <bounce/>
            <friction>
              <torsional>
                <ode/>
              </torsional>
              <ode/>
            </friction>
          </surface>
        </collision>
        <visual name='visual3'>
          <pose frame=''>-0.45 -0.195 0.6 0 -0 0</pose>
          <geometry>
            <box>
              <size>0.02 0.4 1.2</size>
            </box>
          </geometry>
          <material>
            <script>
              <uri>file://media/materials/scripts/gazebo.material</uri>
              <name>Gazebo/Wood</name>
            </script>
          </material>
        </visual>
        <collision name='bottom'>
          <pose frame=''>0 -0.195 0.03 0 -0 0</pose>
          <geometry>
            <box>
              <size>0.88 0.4 0.06</size>
            </box>
          </geometry>
          <max_contacts>10</max_contacts>
          <surface>
            <contact>
              <ode/>
            </contact>
            <bounce/>
            <friction>
              <torsional>
                <ode/>
              </torsional>
              <ode/>
            </friction>
          </surface>
        </collision>
        <visual name='visual4'>
          <pose frame=''>0 -0.195 0.03 0 -0 0</pose>
          <geometry>
            <box>
              <size>0.88 0.4 0.06</size>
            </box>
          </geometry>
          <material>
            <script>
              <uri>file://media/materials/scripts/gazebo.material</uri>
              <name>Gazebo/Wood</name>
            </script>
          </material>
        </visual>
        <collision name='top'>
          <pose frame=''>0 -0.195 1.19 0 -0 0</pose>
          <geometry>
            <box>
              <size>0.88 0.4 0.02</size>
            </box>
          </geometry>
          <max_contacts>10</max_contacts>
          <surface>
            <contact>
              <ode/>
            </contact>
            <bounce/>
            <friction>
              <torsional>
                <ode/>
              </torsional>
              <ode/>
            </friction>
          </surface>
        </collision>
        <visual name='visual5'>
          <pose frame=''>0 -0.195 1.19 0 -0 0</pose>
          <geometry>
            <box>
              <size>0.88 0.4 0.02</size>
            </box>
          </geometry>
          <material>
            <script>
              <uri>file://media/materials/scripts/gazebo.material</uri>
              <name>Gazebo/Wood</name>
            </script>
          </material>
        </visual>
        <collision name='low_shelf'>
          <pose frame=''>0 -0.195 0.43 0 -0 0</pose>
          <geometry>
            <box>
              <size>0.88 0.4 0.02</size>
            </box>
          </geometry>
          <max_contacts>10</max_contacts>
          <surface>
            <contact>
              <ode/>
            </contact>
            <bounce/>
            <friction>
              <torsional>
                <ode/>
              </torsional>
              <ode/>
            </friction>
          </surface>
        </collision>
        <visual name='visual6'>
          <pose frame=''>0 -0.195 0.43 0 -0 0</pose>
          <geometry>
            <box>
              <size>0.88 0.4 0.02</size>
            </box>
          </geometry>
          <material>
            <script>
              <uri>file://media/materials/scripts/gazebo.material</uri>
              <name>Gazebo/Wood</name>
            </script>
          </material>
        </visual>
        <collision name='high_shelf'>
          <pose frame=''>0 -0.195 0.8 0 -0 0</pose>
          <geometry>
            <box>
              <size>0.88 0.4 0.02</size>
            </box>
          </geometry>
          <max_contacts>10</max_contacts>
          <surface>
            <contact>
              <ode/>
            </contact>
            <bounce/>
            <friction>
              <torsional>
                <ode/>
              </torsional>
              <ode/>
            </friction>
          </surface>
        </collision>
        <visual name='visual7'>
          <pose frame=''>0 -0.195 0.8 0 -0 0</pose>
          <geometry>
            <box>
              <size>0.88 0.4 0.02</size>
            </box>
          </geometry>
          <material>
            <script>
              <uri>file://media/materials/scripts/gazebo.material</uri>
              <name>Gazebo/Wood</name>
            </script>
          </material>
        </visual>
        <self_collide>0</self_collide>
        <kinematic>0</kinematic>
      </link>
      <pose frame=''>2.0905 0.186237 0 0 -0 0</pose>
    </model>
    <model name='law_office'>
      <static>1</static>
      <link name='link'>
        <collision name='collision'>
          <pose frame=''>0 0 6.96244 0 -0 0</pose>
          <geometry>
            <box>
              <size>6.84401 5.43165 13.9249</size>
            </box>
          </geometry>
          <max_contacts>10</max_contacts>
          <surface>
            <contact>
              <ode/>
            </contact>
            <bounce/>
            <friction>
              <torsional>
                <ode/>
              </torsional>
              <ode/>
            </friction>
          </surface>
        </collision>
        <visual name='visual'>
          <geometry>
            <mesh>
              <uri>model://law_office/meshes/law_office.dae</uri>
            </mesh>
          </geometry>
        </visual>
        <self_collide>0</self_collide>
        <kinematic>0</kinematic>
      </link>
      <pose frame=''>-1.41521 5.41341 0 0 -0 0</pose>
    </model>
    <model name='nist'>
      <static>1</static>
      <link name='nist_maze_wall_triple_holes_120_link'>
        <pose frame=''>0 0 0 0 -0 0</pose>
        <collision name='collision'>
          <geometry>
            <mesh>
              <uri>model://nist_maze_wall_triple_holes_120/meshes/nist_maze_wall_triple_holes_120.dae</uri>
              <scale>1 1 1</scale>
            </mesh>
          </geometry>
          <max_contacts>10</max_contacts>
          <surface>
            <contact>
              <ode/>
            </contact>
            <bounce/>
            <friction>
              <torsional>
                <ode/>
              </torsional>
              <ode/>
            </friction>
          </surface>
        </collision>
        <visual name='visual'>
          <geometry>
            <mesh>
              <uri>model://nist_maze_wall_triple_holes_120/meshes/nist_maze_wall_triple_holes_120.dae</uri>
              <scale>1 1 1</scale>
            </mesh>
          </geometry>
        </visual>
        <self_collide>0</self_collide>
        <kinematic>0</kinematic>
      </link>
      <pose frame=''>-1.34088 -2.47405 0 0 -0 0</pose>
    </model>
    <model name='person_walking'>
      <link name='link'>
        <inertial>
          <pose frame=''>0 0 0.95 0 -0 0</pose>
          <mass>80</mass>
          <inertia>
            <ixx>27.82</ixx>
            <ixy>0</ixy>
            <ixz>0</ixz>
            <iyy>24.88</iyy>
            <iyz>0</iyz>
            <izz>4.57</izz>
          </inertia>
        </inertial>
        <collision name='bottom'>
          <pose frame=''>0 0 0.01 0 -0 0</pose>
          <geometry>
            <box>
              <size>0.35 0.75 0.02</size>
            </box>
          </geometry>
          <max_contacts>10</max_contacts>
          <surface>
            <contact>
              <ode/>
            </contact>
            <bounce/>
            <friction>
              <torsional>
                <ode/>
              </torsional>
              <ode/>
            </friction>
          </surface>
        </collision>
        <collision name='person'>
          <pose frame=''>0 0 -0.02 0 -0 0</pose>
          <geometry>
            <mesh>
              <uri>model://person_walking/meshes/walking.dae</uri>
            </mesh>
          </geometry>
          <max_contacts>10</max_contacts>
          <surface>
            <contact>
              <ode/>
            </contact>
            <bounce/>
            <friction>
              <torsional>
                <ode/>
              </torsional>
              <ode/>
            </friction>
          </surface>
        </collision>
        <visual name='visual'>
          <pose frame=''>0 0 -0.02 0 -0 0</pose>
          <geometry>
            <mesh>
              <uri>model://person_walking/meshes/walking.dae</uri>
            </mesh>
          </geometry>
        </visual>
        <self_collide>0</self_collide>
        <kinematic>0</kinematic>
      </link>
      <pose frame=''>1.98628 -2.23714 0 0 -0 0</pose>
    </model>
    <model name='pioneer2dx'>
      <link name='chassis'>
        <pose frame=''>0 0 0.16 0 -0 0</pose>
        <inertial>
          <mass>5.67</mass>
          <inertia>
            <ixx>0.07</ixx>
            <iyy>0.08</iyy>
            <izz>0.1</izz>
            <ixy>0</ixy>
            <ixz>0</ixz>
            <iyz>0</iyz>
          </inertia>
        </inertial>
        <collision name='collision'>
          <geometry>
            <box>
              <size>0.445 0.277 0.17</size>
            </box>
          </geometry>
          <max_contacts>10</max_contacts>
          <surface>
            <contact>
              <ode/>
            </contact>
            <bounce/>
            <friction>
              <torsional>
                <ode/>
              </torsional>
              <ode/>
            </friction>
          </surface>
        </collision>
        <collision name='castor_collision'>
          <pose frame=''>-0.2 0 -0.12 0 -0 0</pose>
          <geometry>
            <sphere>
              <radius>0.04</radius>
            </sphere>
          </geometry>
          <surface>
            <friction>
              <ode>
                <mu>0</mu>
                <mu2>0</mu2>
                <slip1>1</slip1>
                <slip2>1</slip2>
              </ode>
              <torsional>
                <ode/>
              </torsional>
            </friction>
            <contact>
              <ode/>
            </contact>
            <bounce/>
          </surface>
          <max_contacts>10</max_contacts>
        </collision>
        <visual name='visual'>
          <pose frame=''>0 0 0.04 0 -0 0</pose>
          <geometry>
            <mesh>
              <uri>model://pioneer2dx/meshes/chassis.dae</uri>
            </mesh>
          </geometry>
        </visual>
        <visual name='castor_visual'>
          <pose frame=''>-0.2 0 -0.12 0 -0 0</pose>
          <geometry>
            <sphere>
              <radius>0.04</radius>
            </sphere>
          </geometry>
          <material>
            <script>
              <uri>file://media/materials/scripts/gazebo.material</uri>
              <name>Gazebo/FlatBlack</name>
            </script>
          </material>
        </visual>
        <self_collide>0</self_collide>
        <kinematic>0</kinematic>
      </link>
      <link name='right_wheel'>
        <pose frame=''>0.1 -0.17 0.11 -0 1.5707 1.5707</pose>
        <inertial>
          <mass>1.5</mass>
          <inertia>
            <ixx>0.0051</ixx>
            <iyy>0.0051</iyy>
            <izz>0.009</izz>
            <ixy>0</ixy>
            <ixz>0</ixz>
            <iyz>0</iyz>
          </inertia>
        </inertial>
        <collision name='collision'>
          <geometry>
            <cylinder>
              <radius>0.11</radius>
              <length>0.05</length>
            </cylinder>
          </geometry>
          <surface>
            <friction>
              <ode>
                <mu>100000</mu>
                <mu2>100000</mu2>
                <slip1>0</slip1>
                <slip2>0</slip2>
              </ode>
              <torsional>
                <ode/>
              </torsional>
            </friction>
            <contact>
              <ode/>
            </contact>
            <bounce/>
          </surface>
          <max_contacts>10</max_contacts>
        </collision>
        <visual name='visual'>
          <geometry>
            <cylinder>
              <radius>0.11</radius>
              <length>0.05</length>
            </cylinder>
          </geometry>
          <material>
            <script>
              <uri>file://media/materials/scripts/gazebo.material</uri>
              <name>Gazebo/FlatBlack</name>
            </script>
          </material>
        </visual>
        <self_collide>0</self_collide>
        <kinematic>0</kinematic>
      </link>
      <link name='left_wheel'>
        <pose frame=''>0.1 0.17 0.11 -0 1.5707 1.5707</pose>
        <inertial>
          <mass>1.5</mass>
          <inertia>
            <ixx>0.0051</ixx>
            <iyy>0.0051</iyy>
            <izz>0.009</izz>
            <ixy>0</ixy>
            <ixz>0</ixz>
            <iyz>0</iyz>
          </inertia>
        </inertial>
        <collision name='collision'>
          <geometry>
            <cylinder>
              <radius>0.11</radius>
              <length>0.05</length>
            </cylinder>
          </geometry>
          <surface>
            <friction>
              <ode>
                <mu>100000</mu>
                <mu2>100000</mu2>
                <slip1>0</slip1>
                <slip2>0</slip2>
              </ode>
              <torsional>
                <ode/>
              </torsional>
            </friction>
            <contact>
              <ode/>
            </contact>
            <bounce/>
          </surface>
          <max_contacts>10</max_contacts>
        </collision>
        <visual name='visual'>
          <geometry>
            <cylinder>
              <radius>0.11</radius>
              <length>0.05</length>
            </cylinder>
          </geometry>
          <material>
            <script>
              <uri>file://media/materials/scripts/gazebo.material</uri>
              <name>Gazebo/FlatBlack</name>
            </script>
          </material>
        </visual>
        <self_collide>0</self_collide>
        <kinematic>0</kinematic>
      </link>
      <joint name='left_wheel_hinge' type='revolute'>
        <pose frame=''>0 0 -0.03 0 -0 0</pose>
        <child>left_wheel</child>
        <parent>chassis</parent>
        <axis>
          <xyz>0 1 0</xyz>
          <use_parent_model_frame>1</use_parent_model_frame>
          <limit>
            <lower>-1e+16</lower>
            <upper>1e+16</upper>
          </limit>
          <dynamics>
            <spring_reference>0</spring_reference>
            <spring_stiffness>0</spring_stiffness>
          </dynamics>
        </axis>
      </joint>
      <joint name='right_wheel_hinge' type='revolute'>
        <pose frame=''>0 0 0.03 0 -0 0</pose>
        <child>right_wheel</child>
        <parent>chassis</parent>
        <axis>
          <xyz>0 1 0</xyz>
          <use_parent_model_frame>1</use_parent_model_frame>
          <limit>
            <lower>-1e+16</lower>
            <upper>1e+16</upper>
          </limit>
          <dynamics>
            <spring_reference>0</spring_reference>
            <spring_stiffness>0</spring_stiffness>
          </dynamics>
        </axis>
      </joint>
      <plugin name='diff_drive' filename='libDiffDrivePlugin.so'>
        <left_joint>left_wheel_hinge</left_joint>
        <right_joint>right_wheel_hinge</right_joint>
        <torque>5</torque>
      </plugin>
      <pose frame=''>0.35951 -2.29686 0 0 -0 0</pose>
    </model>
    <model name='simple_arm'>
      <link name='arm_base'>
        <inertial>
          <pose frame=''>0 0 0.00099 0 -0 0</pose>
          <inertia>
            <ixx>1.11</ixx>
            <ixy>0</ixy>
            <ixz>0</ixz>
            <iyy>100.11</iyy>
            <iyz>0</iyz>
            <izz>1.01</izz>
          </inertia>
          <mass>101</mass>
        </inertial>
        <collision name='arm_base_geom'>
          <pose frame=''>0 0 0.05 0 -0 0</pose>
          <geometry>
            <box>
              <size>1 1 0.1</size>
            </box>
          </geometry>
          <max_contacts>10</max_contacts>
          <surface>
            <contact>
              <ode/>
            </contact>
            <bounce/>
            <friction>
              <torsional>
                <ode/>
              </torsional>
              <ode/>
            </friction>
          </surface>
        </collision>
        <visual name='arm_base_geom_visual'>
          <pose frame=''>0 0 0.05 0 -0 0</pose>
          <geometry>
            <box>
              <size>1 1 0.1</size>
            </box>
          </geometry>
          <material>
            <script>
              <uri>file://media/materials/scripts/gazebo.material</uri>
              <name>Gazebo/Blue</name>
            </script>
          </material>
        </visual>
        <collision name='arm_base_geom_arm_trunk'>
          <pose frame=''>0 0 0.6 0 -0 0</pose>
          <geometry>
            <cylinder>
              <radius>0.05</radius>
              <length>1</length>
            </cylinder>
          </geometry>
          <max_contacts>10</max_contacts>
          <surface>
            <contact>
              <ode/>
            </contact>
            <bounce/>
            <friction>
              <torsional>
                <ode/>
              </torsional>
              <ode/>
            </friction>
          </surface>
        </collision>
        <visual name='arm_base_geom_arm_trunk_visual'>
          <pose frame=''>0 0 0.6 0 -0 0</pose>
          <geometry>
            <cylinder>
              <radius>0.05</radius>
              <length>1</length>
            </cylinder>
          </geometry>
          <material>
            <script>
              <uri>file://media/materials/scripts/gazebo.material</uri>
              <name>Gazebo/Red</name>
            </script>
          </material>
        </visual>
        <self_collide>0</self_collide>
        <kinematic>0</kinematic>
      </link>
      <link name='arm_shoulder_pan'>
        <pose frame=''>0 0 1.1 0 -0 0</pose>
        <inertial>
          <pose frame=''>0.045455 0 0 0 -0 0</pose>
          <inertia>
            <ixx>0.011</ixx>
            <ixy>0</ixy>
            <ixz>0</ixz>
            <iyy>0.0225</iyy>
            <iyz>0</iyz>
            <izz>0.0135</izz>
          </inertia>
          <mass>1.1</mass>
        </inertial>
        <collision name='arm_shoulder_pan_geom'>
          <pose frame=''>0 0 0.05 0 -0 0</pose>
          <geometry>
            <cylinder>
              <radius>0.05</radius>
              <length>0.1</length>
            </cylinder>
          </geometry>
          <max_contacts>10</max_contacts>
          <surface>
            <contact>
              <ode/>
            </contact>
            <bounce/>
            <friction>
              <torsional>
                <ode/>
              </torsional>
              <ode/>
            </friction>
          </surface>
        </collision>
        <visual name='arm_shoulder_pan_geom_visual'>
          <pose frame=''>0 0 0.05 0 -0 0</pose>
          <geometry>
            <cylinder>
              <radius>0.05</radius>
              <length>0.1</length>
            </cylinder>
          </geometry>
          <material>
            <script>
              <uri>file://media/materials/scripts/gazebo.material</uri>
              <name>Gazebo/Yellow</name>
            </script>
          </material>
        </visual>
        <collision name='arm_shoulder_pan_geom_arm_shoulder'>
          <pose frame=''>0.55 0 0.05 0 -0 0</pose>
          <geometry>
            <box>
              <size>1 0.05 0.1</size>
            </box>
          </geometry>
          <max_contacts>10</max_contacts>
          <surface>
            <contact>
              <ode/>
            </contact>
            <bounce/>
            <friction>
              <torsional>
                <ode/>
              </torsional>
              <ode/>
            </friction>
          </surface>
        </collision>
        <visual name='arm_shoulder_pan_geom_arm_shoulder_visual'>
          <pose frame=''>0.55 0 0.05 0 -0 0</pose>
          <geometry>
            <box>
              <size>1 0.05 0.1</size>
            </box>
          </geometry>
          <material>
            <script>
              <uri>file://media/materials/scripts/gazebo.material</uri>
              <name>Gazebo/Yellow</name>
            </script>
          </material>
        </visual>
        <self_collide>0</self_collide>
        <kinematic>0</kinematic>
      </link>
      <link name='arm_elbow_pan'>
        <pose frame=''>1.05 0 1.1 0 -0 0</pose>
        <inertial>
          <pose frame=''>0.0875 0 0.083333 0 -0 0</pose>
          <inertia>
            <ixx>0.031</ixx>
            <ixy>0</ixy>
            <ixz>0.005</ixz>
            <iyy>0.07275</iyy>
            <iyz>0</iyz>
            <izz>0.04475</izz>
          </inertia>
          <mass>1.2</mass>
        </inertial>
        <collision name='arm_elbow_pan_geom'>
          <pose frame=''>0 0 0.1 0 -0 0</pose>
          <geometry>
            <cylinder>
              <radius>0.05</radius>
              <length>0.2</length>
            </cylinder>
          </geometry>
          <max_contacts>10</max_contacts>
          <surface>
            <contact>
              <ode/>
            </contact>
            <bounce/>
            <friction>
              <torsional>
                <ode/>
              </torsional>
              <ode/>
            </friction>
          </surface>
        </collision>
        <visual name='arm_elbow_pan_geom_visual'>
          <pose frame=''>0 0 0.1 0 -0 0</pose>
          <geometry>
            <cylinder>
              <radius>0.05</radius>
              <length>0.2</length>
            </cylinder>
          </geometry>
          <material>
            <script>
              <uri>file://media/materials/scripts/gazebo.material</uri>
              <name>Gazebo/Red</name>
            </script>
          </material>
        </visual>
        <collision name='arm_elbow_pan_geom_arm_elbow'>
          <pose frame=''>0.3 0 0.15 0 -0 0</pose>
          <geometry>
            <box>
              <size>0.5 0.03 0.1</size>
            </box>
          </geometry>
          <max_contacts>10</max_contacts>
          <surface>
            <contact>
              <ode/>
            </contact>
            <bounce/>
            <friction>
              <torsional>
                <ode/>
              </torsional>
              <ode/>
            </friction>
          </surface>
        </collision>
        <visual name='arm_elbow_pan_geom_arm_elbow_visual'>
          <pose frame=''>0.3 0 0.15 0 -0 0</pose>
          <geometry>
            <box>
              <size>0.5 0.03 0.1</size>
            </box>
          </geometry>
          <material>
            <script>
              <uri>file://media/materials/scripts/gazebo.material</uri>
              <name>Gazebo/Yellow</name>
            </script>
          </material>
        </visual>
        <collision name='arm_elbow_pan_geom_arm_wrist'>
          <pose frame=''>0.55 0 0.15 0 -0 0</pose>
          <geometry>
            <cylinder>
              <radius>0.05</radius>
              <length>0.3</length>
            </cylinder>
          </geometry>
          <max_contacts>10</max_contacts>
          <surface>
            <contact>
              <ode/>
            </contact>
            <bounce/>
            <friction>
              <torsional>
                <ode/>
              </torsional>
              <ode/>
            </friction>
          </surface>
        </collision>
        <visual name='arm_elbow_pan_geom_arm_wrist_visual'>
          <pose frame=''>0.55 0 0.15 0 -0 0</pose>
          <geometry>
            <cylinder>
              <radius>0.05</radius>
              <length>0.3</length>
            </cylinder>
          </geometry>
          <material>
            <script>
              <uri>file://media/materials/scripts/gazebo.material</uri>
              <name>Gazebo/Red</name>
            </script>
          </material>
        </visual>
        <self_collide>0</self_collide>
        <kinematic>0</kinematic>
      </link>
      <link name='arm_wrist_lift'>
        <pose frame=''>1.6 0 1.05 0 -0 0</pose>
        <inertial>
          <pose frame=''>0 0 0 0 -0 0</pose>
          <inertia>
            <ixx>0.01</ixx>
            <ixy>0</ixy>
            <ixz>0</ixz>
            <iyy>0.01</iyy>
            <iyz>0</iyz>
            <izz>0.001</izz>
          </inertia>
          <mass>0.1</mass>
        </inertial>
        <collision name='arm_wrist_lift_geom'>
          <pose frame=''>0 0 0.5 0 -0 0</pose>
          <geometry>
            <cylinder>
              <radius>0.03</radius>
              <length>1</length>
            </cylinder>
          </geometry>
          <max_contacts>10</max_contacts>
          <surface>
            <contact>
              <ode/>
            </contact>
            <bounce/>
            <friction>
              <torsional>
                <ode/>
              </torsional>
              <ode/>
            </friction>
          </surface>
        </collision>
        <visual name='arm_wrist_lift_geom_visual'>
          <pose frame=''>0 0 0.5 0 -0 0</pose>
          <geometry>
            <cylinder>
              <radius>0.03</radius>
              <length>1</length>
            </cylinder>
          </geometry>
          <material>
            <script>
              <uri>file://media/materials/scripts/gazebo.material</uri>
              <name>Gazebo/Yellow</name>
            </script>
          </material>
        </visual>
        <self_collide>0</self_collide>
        <kinematic>0</kinematic>
      </link>
      <link name='arm_wrist_roll'>
        <pose frame=''>1.6 0 1 0 -0 0</pose>
        <inertial>
          <pose frame=''>0 0 0 0 -0 0</pose>
          <inertia>
            <ixx>0.01</ixx>
            <ixy>0</ixy>
            <ixz>0</ixz>
            <iyy>0.01</iyy>
            <iyz>0</iyz>
            <izz>0.001</izz>
          </inertia>
          <mass>0.1</mass>
        </inertial>
        <collision name='arm_wrist_roll_geom'>
          <pose frame=''>0 0 0.025 0 -0 0</pose>
          <geometry>
            <cylinder>
              <radius>0.05</radius>
              <length>0.05</length>
            </cylinder>
          </geometry>
          <max_contacts>10</max_contacts>
          <surface>
            <contact>
              <ode/>
            </contact>
            <bounce/>
            <friction>
              <torsional>
                <ode/>
              </torsional>
              <ode/>
            </friction>
          </surface>
        </collision>
        <visual name='arm_wrist_roll_geom_visual'>
          <pose frame=''>0 0 0.025 0 -0 0</pose>
          <geometry>
            <cylinder>
              <radius>0.05</radius>
              <length>0.05</length>
            </cylinder>
          </geometry>
          <material>
            <script>
              <uri>file://media/materials/scripts/gazebo.material</uri>
              <name>Gazebo/Red</name>
            </script>
          </material>
        </visual>
        <self_collide>0</self_collide>
        <kinematic>0</kinematic>
      </link>
      <joint name='arm_shoulder_pan_joint' type='revolute'>
        <parent>arm_base</parent>
        <child>arm_shoulder_pan</child>
        <axis>
          <dynamics>
            <damping>1</damping>
            <friction>0</friction>
            <spring_reference>0</spring_reference>
            <spring_stiffness>0</spring_stiffness>
          </dynamics>
          <xyz>0 0 1</xyz>
          <use_parent_model_frame>1</use_parent_model_frame>
          <limit>
            <lower>-1e+16</lower>
            <upper>1e+16</upper>
          </limit>
        </axis>
      </joint>
      <joint name='arm_elbow_pan_joint' type='revolute'>
        <parent>arm_shoulder_pan</parent>
        <child>arm_elbow_pan</child>
        <axis>
          <dynamics>
            <damping>1</damping>
            <friction>0</friction>
            <spring_reference>0</spring_reference>
            <spring_stiffness>0</spring_stiffness>
          </dynamics>
          <xyz>0 0 1</xyz>
          <use_parent_model_frame>1</use_parent_model_frame>
          <limit>
            <lower>-1e+16</lower>
            <upper>1e+16</upper>
          </limit>
        </axis>
      </joint>
      <joint name='arm_wrist_lift_joint' type='prismatic'>
        <parent>arm_elbow_pan</parent>
        <child>arm_wrist_lift</child>
        <axis>
          <dynamics>
            <damping>1</damping>
            <friction>0</friction>
            <spring_reference>0</spring_reference>
            <spring_stiffness>0</spring_stiffness>
          </dynamics>
          <limit>
            <lower>-0.8</lower>
            <upper>0.1</upper>
          </limit>
          <xyz>0 0 1</xyz>
          <use_parent_model_frame>1</use_parent_model_frame>
        </axis>
      </joint>
      <joint name='arm_wrist_roll_joint' type='revolute'>
        <parent>arm_wrist_lift</parent>
        <child>arm_wrist_roll</child>
        <axis>
          <dynamics>
            <damping>1</damping>
            <friction>0</friction>
            <spring_reference>0</spring_reference>
            <spring_stiffness>0</spring_stiffness>
          </dynamics>
          <limit>
            <lower>-2.99999</lower>
            <upper>2.99999</upper>
          </limit>
          <xyz>0 0 1</xyz>
          <use_parent_model_frame>1</use_parent_model_frame>
        </axis>
      </joint>
      <pose frame=''>3.33402 -2.64134 0 0 -0 0</pose>
    </model>
    <model name='Speed limit'>
      <static>1</static>
      <link name='link'>
        <collision name='collision'>
          <geometry>
            <mesh>
              <scale>10 10 10</scale>
              <uri>model://speed_limit_sign/meshes/speed_limit_sign.dae</uri>
            </mesh>
          </geometry>
          <max_contacts>10</max_contacts>
          <surface>
            <contact>
              <ode/>
            </contact>
            <bounce/>
            <friction>
              <torsional>
                <ode/>
              </torsional>
              <ode/>
            </friction>
          </surface>
        </collision>
        <visual name='visual'>
          <geometry>
            <mesh>
              <scale>10 10 10</scale>
              <uri>model://speed_limit_sign/meshes/speed_limit_sign.dae</uri>
            </mesh>
          </geometry>
        </visual>
        <self_collide>0</self_collide>
        <kinematic>0</kinematic>
      </link>
      <pose frame=''>-1.04349 -5.18838 0 0 -0 0</pose>
    </model>
    <model name='submarine'>
      <pose frame=''>8.85856 3.2043 1.5 1.5708 -0 0</pose>
      <link name='body'>
        <pose frame=''>0 0 0 0 -0 0</pose>
        <inertial>
          <mass>251.327</mass>
          <inertia>
            <ixx>86.2891</ixx>
            <ixy>0</ixy>
            <ixz>0</ixz>
            <iyy>86.2891</iyy>
            <iyz>0</iyz>
            <izz>5.02655</izz>
          </inertia>
        </inertial>
        <visual name='body_visual'>
          <geometry>
            <cylinder>
              <radius>0.2</radius>
              <length>2</length>
            </cylinder>
          </geometry>
          <material>
            <script>
              <uri>file://media/materials/scripts/gazebo.material</uri>
              <name>Gazebo/Yellow</name>
            </script>
          </material>
        </visual>
        <collision name='body_collision'>
          <geometry>
            <cylinder>
              <radius>0.2</radius>
              <length>2</length>
            </cylinder>
          </geometry>
          <max_contacts>10</max_contacts>
          <surface>
            <contact>
              <ode/>
            </contact>
            <bounce/>
            <friction>
              <torsional>
                <ode/>
              </torsional>
              <ode/>
            </friction>
          </surface>
        </collision>
        <visual name='spacer_visual'>
          <pose frame=''>0 0 1.05855 0 -0 0</pose>
          <geometry>
            <cylinder>
              <radius>0.0933402</radius>
              <length>0.127211</length>
            </cylinder>
          </geometry>
          <material>
            <script>
              <uri>file://media/materials/scripts/gazebo.material</uri>
              <name>Gazebo/Yellow</name>
            </script>
          </material>
        </visual>
        <self_collide>0</self_collide>
        <kinematic>0</kinematic>
      </link>
      <link name='propeller'>
        <pose frame=''>0 0 1.09 3.14159 -0 0</pose>
        <inertial>
          <mass>21.82</mass>
          <inertia>
            <ixx>0.459994</ixx>
            <ixy>0</ixy>
            <ixz>0</ixz>
            <iyy>0.459994</iyy>
            <iyz>0</iyz>
            <izz>0.909167</izz>
          </inertia>
        </inertial>
        <visual name='blade1_visual'>
          <pose frame=''>0.34334 0 0 0.785398 -0 0</pose>
          <geometry>
            <box>
              <size>0.5 0.2 0.05455</size>
            </box>
          </geometry>
          <material>
            <script>
              <uri>file://media/materials/scripts/gazebo.material</uri>
              <name>Gazebo/Yellow</name>
            </script>
          </material>
        </visual>
        <collision name='blade1_collision'>
          <pose frame=''>0.34334 0 0 0.785398 -0 0</pose>
          <geometry>
            <box>
              <size>0.5 0.2 0.05455</size>
            </box>
          </geometry>
          <max_contacts>10</max_contacts>
          <surface>
            <contact>
              <ode/>
            </contact>
            <bounce/>
            <friction>
              <torsional>
                <ode/>
              </torsional>
              <ode/>
            </friction>
          </surface>
        </collision>
        <visual name='blade2_visual'>
          <pose frame=''>0 0.34334 0 0.785398 0 1.5708</pose>
          <geometry>
            <box>
              <size>0.5 0.2 0.05455</size>
            </box>
          </geometry>
          <material>
            <script>
              <uri>file://media/materials/scripts/gazebo.material</uri>
              <name>Gazebo/Yellow</name>
            </script>
          </material>
        </visual>
        <collision name='blade2_collision'>
          <pose frame=''>0 0.34334 0 0.785398 0 1.5708</pose>
          <geometry>
            <box>
              <size>0.5 0.2 0.05455</size>
            </box>
          </geometry>
          <max_contacts>10</max_contacts>
          <surface>
            <contact>
              <ode/>
            </contact>
            <bounce/>
            <friction>
              <torsional>
                <ode/>
              </torsional>
              <ode/>
            </friction>
          </surface>
        </collision>
        <visual name='blade3_visual'>
          <pose frame=''>-0.34334 -0 0 -0.785398 0 0</pose>
          <geometry>
            <box>
              <size>0.5 0.2 0.05455</size>
            </box>
          </geometry>
          <material>
            <script>
              <uri>file://media/materials/scripts/gazebo.material</uri>
              <name>Gazebo/Yellow</name>
            </script>
          </material>
        </visual>
        <collision name='blade3_collision'>
          <pose frame=''>-0.34334 -0 0 -0.785398 0 0</pose>
          <geometry>
            <box>
              <size>0.5 0.2 0.05455</size>
            </box>
          </geometry>
          <max_contacts>10</max_contacts>
          <surface>
            <contact>
              <ode/>
            </contact>
            <bounce/>
            <friction>
              <torsional>
                <ode/>
              </torsional>
              <ode/>
            </friction>
          </surface>
        </collision>
        <visual name='blade4_visual'>
          <pose frame=''>-0 -0.34334 0 -0.785398 -0 1.5708</pose>
          <geometry>
            <box>
              <size>0.5 0.2 0.05455</size>
            </box>
          </geometry>
          <material>
            <script>
              <uri>file://media/materials/scripts/gazebo.material</uri>
              <name>Gazebo/Yellow</name>
            </script>
          </material>
        </visual>
        <collision name='blade4_collision'>
          <pose frame=''>-0 -0.34334 0 -0.785398 -0 1.5708</pose>
          <geometry>
            <box>
              <size>0.5 0.2 0.05455</size>
            </box>
          </geometry>
          <max_contacts>10</max_contacts>
          <surface>
            <contact>
              <ode/>
            </contact>
            <bounce/>
            <friction>
              <torsional>
                <ode/>
              </torsional>
              <ode/>
            </friction>
          </surface>
        </collision>
        <self_collide>0</self_collide>
        <kinematic>0</kinematic>
      </link>
      <joint name='spinning_joint' type='revolute'>
        <parent>body</parent>
        <child>propeller</child>
        <axis>
          <xyz>0 0 1</xyz>
          <use_parent_model_frame>1</use_parent_model_frame>
          <limit>
            <lower>-1e+12</lower>
            <upper>1e+12</upper>
            <effort>-1</effort>
            <velocity>-1</velocity>
          </limit>
          <dynamics>
            <spring_reference>0</spring_reference>
            <spring_stiffness>0</spring_stiffness>
          </dynamics>
        </axis>
      </joint>
      <allow_auto_disable>1</allow_auto_disable>
      <plugin name='submarine_propeller_1' filename='libLiftDragPlugin.so'>
        <air_density>1000</air_density>
        <cla>1.2535816618911175</cla>
        <cla_stall>-1.4326647564469914</cla_stall>
        <cda>0</cda>
        <cda_stall>1.4326647564469914</cda_stall>
        <alpha_stall>1.396</alpha_stall>
        <a0>0</a0>
        <area>0.27637</area>
        <upward>0 -0.7071067811865476 -0.7071067811865475</upward>
        <forward>0 -0.7071067811865475 0.7071067811865476</forward>
        <link_name>propeller</link_name>
        <cp>0.35 0 0</cp>
      </plugin>
      <plugin name='submarine_propeller_2' filename='libLiftDragPlugin.so'>
        <air_density>1000</air_density>
        <cla>1.2535816618911175</cla>
        <cla_stall>-1.4326647564469914</cla_stall>
        <cda>0</cda>
        <cda_stall>1.4326647564469914</cda_stall>
        <alpha_stall>1.396</alpha_stall>
        <a0>0</a0>
        <area>0.27637</area>
        <upward>-0.7071067811865475 0 -0.7071067811865476</upward>
        <forward>-0.7071067811865476 0 0.7071067811865475</forward>
        <link_name>propeller</link_name>
        <cp>0 -0.35 0</cp>
      </plugin>
      <plugin name='submarine_propeller_3' filename='libLiftDragPlugin.so'>
        <air_density>1000</air_density>
        <cla>1.2535816618911175</cla>
        <cla_stall>-1.4326647564469914</cla_stall>
        <cda>0</cda>
        <cda_stall>1.4326647564469914</cda_stall>
        <alpha_stall>1.396</alpha_stall>
        <a0>0</a0>
        <area>0.27637</area>
        <upward>0 0.7071067811865475 -0.7071067811865476</upward>
        <forward>0 -0.7071067811865476 -0.7071067811865475</forward>
        <link_name>propeller</link_name>
        <cp>-0.35 0 0</cp>
      </plugin>
      <plugin name='submarine_propeller_4' filename='libLiftDragPlugin.so'>
        <air_density>1000</air_density>
        <cla>1.2535816618911175</cla>
        <cla_stall>-1.4326647564469914</cla_stall>
        <cda>0</cda>
        <cda_stall>1.4326647564469914</cda_stall>
        <alpha_stall>1.396</alpha_stall>
        <a0>0</a0>
        <area>0.27637</area>
        <upward>0.7071067811865476 0 -0.7071067811865475</upward>
        <forward>0.7071067811865475 0 0.7071067811865476</forward>
        <link_name>propeller</link_name>
        <cp>0 0.35 0</cp>
      </plugin>
      <plugin name='buoyancy' filename='libBuoyancyPlugin.so'>
        <fluid_density>1000</fluid_density>
      </plugin>
    </model>
    <model name='suv'>
      <static>1</static>
      <link name='link'>
        <collision name='collision'>
          <pose frame=''>0 0 0 0 0 -1.5708</pose>
          <geometry>
            <mesh>
              <scale>0.06 0.06 0.06</scale>
              <uri>model://suv/meshes/suv.obj</uri>
            </mesh>
          </geometry>
          <max_contacts>10</max_contacts>
          <surface>
            <contact>
              <ode/>
            </contact>
            <bounce/>
            <friction>
              <torsional>
                <ode/>
              </torsional>
              <ode/>
            </friction>
          </surface>
        </collision>
        <visual name='visual'>
          <pose frame=''>0 0 0 0 0 -1.5708</pose>
          <geometry>
            <mesh>
              <scale>0.06 0.06 0.06</scale>
              <uri>model://suv/meshes/suv.obj</uri>
            </mesh>
          </geometry>
        </visual>
        <self_collide>0</self_collide>
        <kinematic>0</kinematic>
      </link>
      <pose frame=''>1.12539 -8.77548 0 0 -0 0</pose>
    </model>
    <model name='table'>
      <static>1</static>
      <link name='link'>
        <collision name='surface'>
          <pose frame=''>0 0 1 0 -0 0</pose>
          <geometry>
            <box>
              <size>1.5 0.8 0.03</size>
            </box>
          </geometry>
          <surface>
            <friction>
              <ode>
                <mu>0.6</mu>
                <mu2>0.6</mu2>
              </ode>
              <torsional>
                <ode/>
              </torsional>
            </friction>
            <contact>
              <ode/>
            </contact>
            <bounce/>
          </surface>
          <max_contacts>10</max_contacts>
        </collision>
        <visual name='visual1'>
          <pose frame=''>0 0 1 0 -0 0</pose>
          <geometry>
            <box>
              <size>1.5 0.8 0.03</size>
            </box>
          </geometry>
          <material>
            <script>
              <uri>file://media/materials/scripts/gazebo.material</uri>
              <name>Gazebo/Wood</name>
            </script>
          </material>
        </visual>
        <collision name='front_left_leg'>
          <pose frame=''>0.68 0.38 0.5 0 -0 0</pose>
          <geometry>
            <cylinder>
              <radius>0.02</radius>
              <length>1</length>
            </cylinder>
          </geometry>
          <max_contacts>10</max_contacts>
          <surface>
            <contact>
              <ode/>
            </contact>
            <bounce/>
            <friction>
              <torsional>
                <ode/>
              </torsional>
              <ode/>
            </friction>
          </surface>
        </collision>
        <visual name='front_left_leg'>
          <pose frame=''>0.68 0.38 0.5 0 -0 0</pose>
          <geometry>
            <cylinder>
              <radius>0.02</radius>
              <length>1</length>
            </cylinder>
          </geometry>
          <material>
            <script>
              <uri>file://media/materials/scripts/gazebo.material</uri>
              <name>Gazebo/Grey</name>
            </script>
          </material>
        </visual>
        <collision name='front_right_leg'>
          <pose frame=''>0.68 -0.38 0.5 0 -0 0</pose>
          <geometry>
            <cylinder>
              <radius>0.02</radius>
              <length>1</length>
            </cylinder>
          </geometry>
          <max_contacts>10</max_contacts>
          <surface>
            <contact>
              <ode/>
            </contact>
            <bounce/>
            <friction>
              <torsional>
                <ode/>
              </torsional>
              <ode/>
            </friction>
          </surface>
        </collision>
        <visual name='front_right_leg'>
          <pose frame=''>0.68 -0.38 0.5 0 -0 0</pose>
          <geometry>
            <cylinder>
              <radius>0.02</radius>
              <length>1</length>
            </cylinder>
          </geometry>
          <material>
            <script>
              <uri>file://media/materials/scripts/gazebo.material</uri>
              <name>Gazebo/Grey</name>
            </script>
          </material>
        </visual>
        <collision name='back_right_leg'>
          <pose frame=''>-0.68 -0.38 0.5 0 -0 0</pose>
          <geometry>
            <cylinder>
              <radius>0.02</radius>
              <length>1</length>
            </cylinder>
          </geometry>
          <max_contacts>10</max_contacts>
          <surface>
            <contact>
              <ode/>
            </contact>
            <bounce/>
            <friction>
              <torsional>
                <ode/>
              </torsional>
              <ode/>
            </friction>
          </surface>
        </collision>
        <visual name='back_right_leg'>
          <pose frame=''>-0.68 -0.38 0.5 0 -0 0</pose>
          <geometry>
            <cylinder>
              <radius>0.02</radius>
              <length>1</length>
            </cylinder>
          </geometry>
          <material>
            <script>
              <uri>file://media/materials/scripts/gazebo.material</uri>
              <name>Gazebo/Grey</name>
            </script>
          </material>
        </visual>
        <collision name='back_left_leg'>
          <pose frame=''>-0.68 0.38 0.5 0 -0 0</pose>
          <geometry>
            <cylinder>
              <radius>0.02</radius>
              <length>1</length>
            </cylinder>
          </geometry>
          <max_contacts>10</max_contacts>
          <surface>
            <contact>
              <ode/>
            </contact>
            <bounce/>
            <friction>
              <torsional>
                <ode/>
              </torsional>
              <ode/>
            </friction>
          </surface>
        </collision>
        <visual name='back_left_leg'>
          <pose frame=''>-0.68 0.38 0.5 0 -0 0</pose>
          <geometry>
            <cylinder>
              <radius>0.02</radius>
              <length>1</length>
            </cylinder>
          </geometry>
          <material>
            <script>
              <uri>file://media/materials/scripts/gazebo.material</uri>
              <name>Gazebo/Grey</name>
            </script>
          </material>
        </visual>
        <self_collide>0</self_collide>
        <kinematic>0</kinematic>
      </link>
      <pose frame=''>7.948 -3.40303 0 0 -0 0</pose>
    </model>
    <state world_name='default'>
      <sim_time>449 537000000</sim_time>
      <real_time>1001 424090772</real_time>
      <wall_time>1528565711 851057691</wall_time>
      <iterations>449537</iterations>
      <model name='Speed limit'>
        <pose frame=''>-1.04349 -5.18838 0 0 -0 0</pose>
        <scale>1 1 1</scale>
        <link name='link'>
          <pose frame=''>-1.04349 -5.18838 0 0 -0 0</pose>
          <velocity>0 0 0 0 -0 0</velocity>
          <acceleration>0 0 0 0 -0 0</acceleration>
          <wrench>0 0 0 0 -0 0</wrench>
        </link>
      </model>
      <model name='bill'>
        <pose frame=''>3.64906 -0.794251 0.162004 -7e-06 -0.005011 0.461142</pose>
        <scale>1 1 1</scale>
        <link name='base_link'>
          <pose frame=''>3.64906 -0.794251 0.162004 -7e-06 -0.005011 0.461142</pose>
          <velocity>0.000344 -0.000446 0.002271 0.002002 -0.000516 -0.000879</velocity>
          <acceleration>0.174755 -0.295622 4.31627 -2.58732 -0.234681 -3.13554</acceleration>
          <wrench>0.192248 -0.325213 4.74833 0 -0 0</wrench>
        </link>
        <link name='left_wheel'>
          <pose frame=''>3.73805 -0.97336 0.162005 3.14143 -1.52916 -2.68029</pose>
          <velocity>0.00019 -0.000536 0.001961 -0.001369 -0.001665 -0.00096</velocity>
          <acceleration>0.46936 -0.998097 2.1136 1.57983 0.557914 -0.14633</acceleration>
          <wrench>0.46936 -0.998097 2.1136 0 -0 0</wrench>
        </link>
        <link name='right_wheel'>
          <pose frame=''>3.56006 -0.615142 0.162002 -1e-06 0.696415 0.461141</pose>
          <velocity>0.000498 -0.000363 0.002589 0.002139 0.003242 -0.000874</velocity>
          <acceleration>0.457823 -0.970317 5.09241 0.478442 -0.246313 3.134</acceleration>
          <wrench>0.457823 -0.970317 5.09241 0 -0 0</wrench>
        </link>
      </model>
      <model name='bookshelf'>
        <pose frame=''>2.0905 0.186237 0 0 -0 0</pose>
        <scale>1 1 1</scale>
        <link name='link'>
          <pose frame=''>2.0905 0.186237 0 0 -0 0</pose>
          <velocity>0 0 0 0 -0 0</velocity>
          <acceleration>0 0 0 0 -0 0</acceleration>
          <wrench>0 0 0 0 -0 0</wrench>
        </link>
      </model>
      <model name='ground_plane'>
        <pose frame=''>0 0 0 0 -0 0</pose>
        <scale>1 1 1</scale>
        <link name='link'>
          <pose frame=''>0 0 0 0 -0 0</pose>
          <velocity>0 0 0 0 -0 0</velocity>
          <acceleration>0 0 0 0 -0 0</acceleration>
          <wrench>0 0 0 0 -0 0</wrench>
        </link>
      </model>
      <model name='law_office'>
        <pose frame=''>-1.41521 5.41341 0 0 -0 0</pose>
        <scale>1 1 1</scale>
        <link name='link'>
          <pose frame=''>-1.41521 5.41341 0 0 -0 0</pose>
          <velocity>0 0 0 0 -0 0</velocity>
          <acceleration>0 0 0 0 -0 0</acceleration>
          <wrench>0 0 0 0 -0 0</wrench>
        </link>
      </model>
      <model name='nist'>
        <pose frame=''>-1.34088 -2.47405 0 0 -0 0</pose>
        <scale>1 1 1</scale>
        <link name='nist_maze_wall_triple_holes_120_link'>
          <pose frame=''>-1.34088 -2.47405 0 0 -0 0</pose>
          <velocity>0 0 0 0 -0 0</velocity>
          <acceleration>0 0 0 0 -0 0</acceleration>
          <wrench>0 0 0 0 -0 0</wrench>
        </link>
      </model>
      <model name='person_walking'>
        <pose frame=''>1.98559 -2.23736 -1e-06 -2e-06 1e-06 -0.001482</pose>
        <scale>1 1 1</scale>
        <link name='link'>
          <pose frame=''>1.98559 -2.23736 -1e-06 -2e-06 1e-06 -0.001482</pose>
          <velocity>0 0 0 0 -0 0</velocity>
          <acceleration>1.01029 2.12406 -2.40487 -2.16612 1.08762 0.099824</acceleration>
          <wrench>80.8228 169.925 -192.389 0 -0 0</wrench>
        </link>
      </model>
      <model name='pioneer2dx'>
        <pose frame=''>1.45803 -2.39945 -2e-06 0 1e-05 -0.255714</pose>
        <scale>1 1 1</scale>
        <link name='chassis'>
          <pose frame=''>1.45803 -2.39945 0.159998 0 1e-05 -0.255714</pose>
          <velocity>0.003832 -0.000889 -0.001325 0.010487 0.040226 -3e-05</velocity>
          <acceleration>1.39024 -0.371054 -2.65022 -0.855454 -1.13624 -0.01154</acceleration>
          <wrench>7.88269 -2.10388 -15.0267 0 -0 0</wrench>
        </link>
        <link name='left_wheel'>
          <pose frame=''>1.59778 -2.26028 0.109996 1.57045 1.36283 2.88543</pose>
          <velocity>0.001833 -0.000346 -0.00549 -0.009718 -0.040427 -2.7e-05</velocity>
          <acceleration>-2.62273 0.698148 -10.9769 0.76924 -0.200973 -0.015202</acceleration>
          <wrench>-3.9341 1.04722 -16.4654 0 -0 0</wrench>
        </link>
        <link name='right_wheel'>
          <pose frame=''>1.51178 -2.58922 0.109997 -1.56869 1.52489 -0.253696</pose>
          <velocity>0.001817 -0.000338 -0.005476 -0.009753 -0.040419 -5.3e-05</velocity>
          <acceleration>-2.63239 0.704437 -10.9532 0.73399 -0.192431 -0.06172</acceleration>
          <wrench>-3.94859 1.05665 -16.4299 0 -0 0</wrench>
        </link>
      </model>
      <model name='simple_arm'>
        <pose frame=''>3.33221 -2.64127 0 0 -0 0.004224</pose>
        <scale>1 1 1</scale>
        <link name='arm_base'>
          <pose frame=''>3.33221 -2.64127 0 0 -0 0.004224</pose>
          <velocity>-7e-06 2e-06 0 0 0 -6e-06</velocity>
          <acceleration>0 0 0 0 -0 0</acceleration>
          <wrench>0 0 0 0 -0 0</wrench>
        </link>
        <link name='arm_elbow_pan'>
          <pose frame=''>4.34283 -2.92613 1.1 -1e-06 1.1e-05 -0.21955</pose>
          <velocity>-3e-06 1.7e-05 0 0 -0 1.8e-05</velocity>
          <acceleration>0 0 0 0 2e-06 0</acceleration>
          <wrench>0 0 0 0 -0 0</wrench>
        </link>
        <link name='arm_shoulder_pan'>
          <pose frame=''>3.33221 -2.64127 1.1 -1e-06 -3e-06 -0.274737</pose>
          <velocity>-7e-06 2e-06 0 0 -0 1.5e-05</velocity>
          <acceleration>0 0 0 0 -0 0</acceleration>
          <wrench>0 0 0 0 -0 0</wrench>
        </link>
        <link name='arm_wrist_lift'>
          <pose frame=''>4.87962 -3.04591 0.249989 -1e-06 1.5e-05 -0.219548</pose>
          <velocity>-1e-06 2.6e-05 0 0 -0 1.8e-05</velocity>
          <acceleration>0 0 0 0 -0 0</acceleration>
          <wrench>0 0 0 0 -0 0</wrench>
        </link>
        <link name='arm_wrist_roll'>
          <pose frame=''>4.87962 -3.04591 0.199988 -1e-06 1.6e-05 -0.229664</pose>
          <velocity>-1e-06 2.6e-05 0 0 -0 1.8e-05</velocity>
          <acceleration>0 0 0 0 -0 0</acceleration>
          <wrench>0 0 0 0 -0 0</wrench>
        </link>
      </model>
      <model name='submarine'>
        <pose frame=''>8.85856 3.20328 2.22505 1.72374 -0 0</pose>
        <scale>1 1 1</scale>
        <link name='body'>
          <pose frame=''>8.85856 3.20328 2.22505 1.72374 -0 0</pose>
          <velocity>0 -1.3e-05 0.004674 0.000984 -0 0</velocity>
          <acceleration>0 0 1.5e-05 3e-06 -0 0</acceleration>
          <wrench>0 -3.1e-05 0.003782 0 -0 0</wrench>
        </link>
        <link name='propeller'>
          <pose frame=''>8.85856 2.12601 2.05899 -1.41785 0 0</pose>
          <velocity>0 0.00015 0.003613 0.000984 -0 0</velocity>
          <acceleration>0 1e-06 1.2e-05 3e-06 -0 0</acceleration>
          <wrench>0 3.1e-05 0.000258 0 -0 0</wrench>
        </link>
      </model>
      <model name='suv'>
        <pose frame=''>1.12539 -8.77548 0 0 -0 0</pose>
        <scale>1 1 1</scale>
        <link name='link'>
          <pose frame=''>1.12539 -8.77548 0 0 -0 0</pose>
          <velocity>0 0 0 0 -0 0</velocity>
          <acceleration>0 0 0 0 -0 0</acceleration>
          <wrench>0 0 0 0 -0 0</wrench>
        </link>
      </model>
      <model name='table'>
        <pose frame=''>7.948 -3.40303 0 0 -0 0</pose>
        <scale>1 1 1</scale>
        <link name='link'>
          <pose frame=''>7.948 -3.40303 0 0 -0 0</pose>
          <velocity>0 0 0 0 -0 0</velocity>
          <acceleration>0 0 0 0 -0 0</acceleration>
          <wrench>0 0 0 0 -0 0</wrench>
        </link>
      </model>
      <light name='sun'>
        <pose frame=''>0 0 10 0 -0 0</pose>
      </light>
    </state>
    <gui fullscreen='0'>
      <camera name='user_camera'>
        <pose frame=''>0 0 31.5948 3.14159 1.57079 3.14159</pose>
        <view_controller>orbit</view_controller>
        <projection_type>perspective</projection_type>
      </camera>
    </gui>
  </world>
</sdf>
